Lmod Warning:
-------------------------------------------------------------------------------
The following dependent module(s) are not currently loaded: gdal/3.4.1
(required by: py-gdal-utils/3.4.1_py39)
-------------------------------------------------------------------------------




The following have been reloaded with a version change:
  1) gdal/3.4.1 => gdal/3.5.2     2) proj/8.2.1 => proj/9.1.0

Lmod Warning:
-------------------------------------------------------------------------------
The following dependent module(s) are not currently loaded: gdal/3.4.1
(required by: py-gdal-utils/3.4.1_py39)
-------------------------------------------------------------------------------



/home/users/epavia/.local/lib/python3.9/site-packages/urllib3/__init__.py:35: NotOpenSSLWarning: urllib3 v2 only supports OpenSSL 1.1.1+, currently the 'ssl' module is compiled with 'LibreSSL 3.2.1'. See: https://github.com/urllib3/urllib3/issues/3020
  warnings.warn(
Traceback (most recent call last):
  File "/share/software/user/open/py-gdal-utils/3.4.1_py39/lib/python3.9/site-packages/osgeo/__init__.py", line 29, in swig_import_helper
    return importlib.import_module(mname)
  File "/share/software/user/open/python/3.9.0/lib/python3.9/importlib/__init__.py", line 127, in import_module
    return _bootstrap._gcd_import(name[level:], package, level)
  File "<frozen importlib._bootstrap>", line 1030, in _gcd_import
  File "<frozen importlib._bootstrap>", line 1007, in _find_and_load
  File "<frozen importlib._bootstrap>", line 986, in _find_and_load_unlocked
  File "<frozen importlib._bootstrap>", line 666, in _load_unlocked
  File "<frozen importlib._bootstrap>", line 565, in module_from_spec
  File "<frozen importlib._bootstrap_external>", line 1108, in create_module
  File "<frozen importlib._bootstrap>", line 228, in _call_with_frames_removed
ImportError: libgdal.so.30: cannot open shared object file: No such file or directory

During handling of the above exception, another exception occurred:

Traceback (most recent call last):
  File "/home/users/epavia/gef-rapid-es-assessments/data-cache/derived-products/WorldClim-annual-precip/procure-precip-data.py", line 9, in <module>
    import pygeoprocessing
  File "/home/users/epavia/.local/lib/python3.9/site-packages/pygeoprocessing/__init__.py", line 15, in <module>
    from . import geoprocessing
  File "/home/users/epavia/.local/lib/python3.9/site-packages/pygeoprocessing/geoprocessing.py", line 29, in <module>
    from osgeo import gdal
  File "/share/software/user/open/py-gdal-utils/3.4.1_py39/lib/python3.9/site-packages/osgeo/__init__.py", line 45, in <module>
    _gdal = swig_import_helper()
  File "/share/software/user/open/py-gdal-utils/3.4.1_py39/lib/python3.9/site-packages/osgeo/__init__.py", line 42, in swig_import_helper
    return importlib.import_module('_gdal')
  File "/share/software/user/open/python/3.9.0/lib/python3.9/importlib/__init__.py", line 127, in import_module
    return _bootstrap._gcd_import(name[level:], package, level)
ModuleNotFoundError: No module named '_gdal'
